{
 "cells": [
  {
   "cell_type": "markdown",
   "metadata": {},
   "source": [
    "# Week 5 - Introduction to machine learning\n",
    "\n",
    "### Aims\n",
    "\n",
    "- Demystify some of the ideas behind machine learning by getting hands-on with the Metabrics dataset.\n",
    "- Acquire basic familiarity with Python tools for machine learning.\n",
    "\n",
    "### Learning objectives\n",
    "\n",
    "- Acquire a basic familiarity with the language of machine learning (ML/data mining/AI/pattern recognition/statistics, unsupervised vs. supervised learning, classification and regression, train/test split, bias/variance tradeoff (generalisability), ...)\n",
    "- Implement an end-to-end machine learning classification model using the scikit-learn framework.\n",
    "- Know how to report on the effectiveness of a machine learning model"
   ]
  },
  {
   "cell_type": "markdown",
   "metadata": {},
   "source": [
    "Give an example of something you did yesterday or today which resulted in data which could potentially be mined to discover useful information."
   ]
  },
  {
   "cell_type": "markdown",
   "metadata": {},
   "source": [
    "2 types of methods\n",
    "\n",
    "Prediction Methods (classification, regression):\n",
    "Use some variables to predict unknown or\n",
    "future values of other variables.\n",
    "\n",
    "Description Methods (visualization, clustering, anomaly detection, association mining):\n",
    "Find human-interpretable patterns that\n",
    "describe the data."
   ]
  },
  {
   "cell_type": "markdown",
   "metadata": {},
   "source": [
    "Experimental vs. Observational data - examples"
   ]
  },
  {
   "cell_type": "code",
   "execution_count": null,
   "metadata": {},
   "outputs": [],
   "source": []
  },
  {
   "cell_type": "code",
   "execution_count": 1,
   "metadata": {},
   "outputs": [],
   "source": [
    "import boto3\n",
    "from pathlib import Path\n",
    "\n",
    "s3 = boto3.client('s3')"
   ]
  },
  {
   "cell_type": "code",
   "execution_count": 2,
   "metadata": {},
   "outputs": [
    {
     "ename": "ClientError",
     "evalue": "An error occurred (InvalidAccessKeyId) when calling the ListBuckets operation: The AWS Access Key Id you provided does not exist in our records.",
     "output_type": "error",
     "traceback": [
      "\u001b[0;31m---------------------------------------------------------------------------\u001b[0m",
      "\u001b[0;31mClientError\u001b[0m                               Traceback (most recent call last)",
      "\u001b[0;32m<ipython-input-2-79ec4ef1cbd6>\u001b[0m in \u001b[0;36m<module>\u001b[0;34m\u001b[0m\n\u001b[0;32m----> 1\u001b[0;31m \u001b[0ms3\u001b[0m\u001b[0;34m.\u001b[0m\u001b[0mlist_buckets\u001b[0m\u001b[0;34m(\u001b[0m\u001b[0;34m)\u001b[0m\u001b[0;34m\u001b[0m\u001b[0;34m\u001b[0m\u001b[0m\n\u001b[0m",
      "\u001b[0;32m~/.pyenv/versions/3.8.1/envs/data-science-python-3.8.1/lib/python3.8/site-packages/botocore/client.py\u001b[0m in \u001b[0;36m_api_call\u001b[0;34m(self, *args, **kwargs)\u001b[0m\n\u001b[1;32m    314\u001b[0m                     \"%s() only accepts keyword arguments.\" % py_operation_name)\n\u001b[1;32m    315\u001b[0m             \u001b[0;31m# The \"self\" in this scope is referring to the BaseClient.\u001b[0m\u001b[0;34m\u001b[0m\u001b[0;34m\u001b[0m\u001b[0;34m\u001b[0m\u001b[0m\n\u001b[0;32m--> 316\u001b[0;31m             \u001b[0;32mreturn\u001b[0m \u001b[0mself\u001b[0m\u001b[0;34m.\u001b[0m\u001b[0m_make_api_call\u001b[0m\u001b[0;34m(\u001b[0m\u001b[0moperation_name\u001b[0m\u001b[0;34m,\u001b[0m \u001b[0mkwargs\u001b[0m\u001b[0;34m)\u001b[0m\u001b[0;34m\u001b[0m\u001b[0;34m\u001b[0m\u001b[0m\n\u001b[0m\u001b[1;32m    317\u001b[0m \u001b[0;34m\u001b[0m\u001b[0m\n\u001b[1;32m    318\u001b[0m         \u001b[0m_api_call\u001b[0m\u001b[0;34m.\u001b[0m\u001b[0m__name__\u001b[0m \u001b[0;34m=\u001b[0m \u001b[0mstr\u001b[0m\u001b[0;34m(\u001b[0m\u001b[0mpy_operation_name\u001b[0m\u001b[0;34m)\u001b[0m\u001b[0;34m\u001b[0m\u001b[0;34m\u001b[0m\u001b[0m\n",
      "\u001b[0;32m~/.pyenv/versions/3.8.1/envs/data-science-python-3.8.1/lib/python3.8/site-packages/botocore/client.py\u001b[0m in \u001b[0;36m_make_api_call\u001b[0;34m(self, operation_name, api_params)\u001b[0m\n\u001b[1;32m    633\u001b[0m             \u001b[0merror_code\u001b[0m \u001b[0;34m=\u001b[0m \u001b[0mparsed_response\u001b[0m\u001b[0;34m.\u001b[0m\u001b[0mget\u001b[0m\u001b[0;34m(\u001b[0m\u001b[0;34m\"Error\"\u001b[0m\u001b[0;34m,\u001b[0m \u001b[0;34m{\u001b[0m\u001b[0;34m}\u001b[0m\u001b[0;34m)\u001b[0m\u001b[0;34m.\u001b[0m\u001b[0mget\u001b[0m\u001b[0;34m(\u001b[0m\u001b[0;34m\"Code\"\u001b[0m\u001b[0;34m)\u001b[0m\u001b[0;34m\u001b[0m\u001b[0;34m\u001b[0m\u001b[0m\n\u001b[1;32m    634\u001b[0m             \u001b[0merror_class\u001b[0m \u001b[0;34m=\u001b[0m \u001b[0mself\u001b[0m\u001b[0;34m.\u001b[0m\u001b[0mexceptions\u001b[0m\u001b[0;34m.\u001b[0m\u001b[0mfrom_code\u001b[0m\u001b[0;34m(\u001b[0m\u001b[0merror_code\u001b[0m\u001b[0;34m)\u001b[0m\u001b[0;34m\u001b[0m\u001b[0;34m\u001b[0m\u001b[0m\n\u001b[0;32m--> 635\u001b[0;31m             \u001b[0;32mraise\u001b[0m \u001b[0merror_class\u001b[0m\u001b[0;34m(\u001b[0m\u001b[0mparsed_response\u001b[0m\u001b[0;34m,\u001b[0m \u001b[0moperation_name\u001b[0m\u001b[0;34m)\u001b[0m\u001b[0;34m\u001b[0m\u001b[0;34m\u001b[0m\u001b[0m\n\u001b[0m\u001b[1;32m    636\u001b[0m         \u001b[0;32melse\u001b[0m\u001b[0;34m:\u001b[0m\u001b[0;34m\u001b[0m\u001b[0;34m\u001b[0m\u001b[0m\n\u001b[1;32m    637\u001b[0m             \u001b[0;32mreturn\u001b[0m \u001b[0mparsed_response\u001b[0m\u001b[0;34m\u001b[0m\u001b[0;34m\u001b[0m\u001b[0m\n",
      "\u001b[0;31mClientError\u001b[0m: An error occurred (InvalidAccessKeyId) when calling the ListBuckets operation: The AWS Access Key Id you provided does not exist in our records."
     ]
    }
   ],
   "source": [
    "s3.list_buckets()"
   ]
  },
  {
   "cell_type": "code",
   "execution_count": 3,
   "metadata": {},
   "outputs": [],
   "source": [
    "import re"
   ]
  },
  {
   "cell_type": "code",
   "execution_count": 4,
   "metadata": {},
   "outputs": [
    {
     "name": "stdout",
     "output_type": "stream",
     "text": [
      "Looking in indexes: https://az-pypi:****@artifactory.astrazeneca.net/api/pypi/pypi-virtual/simple\n",
      "Collecting pydantic\n",
      "  Using cached https://artifactory.astrazeneca.net/api/pypi/pypi-virtual/packages/packages/d2/63/d2179649dc52b2d6a484e2647ef067234216edc9ea0e3e30f5adcffe2ab9/pydantic-1.5.1-cp38-cp38-macosx_10_9_x86_64.whl (2.3 MB)\n",
      "Installing collected packages: pydantic\n",
      "Successfully installed pydantic-1.5.1\n",
      "\u001b[33mWARNING: You are using pip version 20.0.2; however, version 20.1.1 is available.\n",
      "You should consider upgrading via the '/Users/ktmx283/.pyenv/versions/3.8.1/envs/data-science-python-3.8.1/bin/python -m pip install --upgrade pip' command.\u001b[0m\n"
     ]
    }
   ],
   "source": [
    "!pip install pydantic"
   ]
  },
  {
   "cell_type": "code",
   "execution_count": 9,
   "metadata": {},
   "outputs": [],
   "source": [
    "import pydantic\n",
    "from typing import Literal"
   ]
  },
  {
   "cell_type": "code",
   "execution_count": 14,
   "metadata": {},
   "outputs": [],
   "source": [
    "class A(pydantic.BaseModel):\n",
    "    a: Literal['a'] = 'a'"
   ]
  },
  {
   "cell_type": "code",
   "execution_count": 17,
   "metadata": {},
   "outputs": [
    {
     "ename": "ValidationError",
     "evalue": "1 validation error for A\na\n  unexpected value; permitted: 'a' (type=value_error.const; given=b; permitted=('a',))",
     "output_type": "error",
     "traceback": [
      "\u001b[0;31m---------------------------------------------------------------------------\u001b[0m",
      "\u001b[0;31mValidationError\u001b[0m                           Traceback (most recent call last)",
      "\u001b[0;32m<ipython-input-17-a2ed001fc68a>\u001b[0m in \u001b[0;36m<module>\u001b[0;34m\u001b[0m\n\u001b[0;32m----> 1\u001b[0;31m \u001b[0mA\u001b[0m\u001b[0;34m(\u001b[0m\u001b[0ma\u001b[0m\u001b[0;34m=\u001b[0m\u001b[0;34m'b'\u001b[0m\u001b[0;34m)\u001b[0m\u001b[0;34m\u001b[0m\u001b[0;34m\u001b[0m\u001b[0m\n\u001b[0m",
      "\u001b[0;32m~/.pyenv/versions/3.8.1/envs/data-science-python-3.8.1/lib/python3.8/site-packages/pydantic/main.cpython-38-darwin.so\u001b[0m in \u001b[0;36mpydantic.main.BaseModel.__init__\u001b[0;34m()\u001b[0m\n",
      "\u001b[0;31mValidationError\u001b[0m: 1 validation error for A\na\n  unexpected value; permitted: 'a' (type=value_error.const; given=b; permitted=('a',))"
     ]
    }
   ],
   "source": [
    "A(a='b')"
   ]
  },
  {
   "cell_type": "code",
   "execution_count": null,
   "metadata": {},
   "outputs": [],
   "source": []
  }
 ],
 "metadata": {
  "kernelspec": {
   "display_name": "Python 3",
   "language": "python",
   "name": "python3"
  },
  "language_info": {
   "codemirror_mode": {
    "name": "ipython",
    "version": 3
   },
   "file_extension": ".py",
   "mimetype": "text/x-python",
   "name": "python",
   "nbconvert_exporter": "python",
   "pygments_lexer": "ipython3",
   "version": "3.8.1"
  }
 },
 "nbformat": 4,
 "nbformat_minor": 4
}
